2021-10-03 23:48:33,220 [INFO] django.utils.autoreload: Watching for file changes with StatReloader
2021-10-04 00:28:18,393 [INFO] neworld: INFO 레벨로 출력
2021-10-04 00:28:18,529 [ERROR] django.request: Internal Server Error: /
Traceback (most recent call last):
  File "/home/ubuntu/venvs/mysite/lib/python3.8/site-packages/django/core/handlers/exception.py", line 47, in inner
    response = get_response(request)
  File "/home/ubuntu/venvs/mysite/lib/python3.8/site-packages/django/core/handlers/base.py", line 179, in _get_response
    response = wrapped_callback(request, *callback_args, **callback_kwargs)
  File "/home/ubuntu/projects/mysite/neworld/views/base_views.py", line 31, in index
    last_real_day = datetime.datetime.strptime(last_real_date.real_date, "%Y-%m-%d")
AttributeError: 'NoneType' object has no attribute 'real_date'
2021-10-04 00:28:21,299 [INFO] neworld: INFO 레벨로 출력
2021-10-04 00:28:21,355 [ERROR] django.request: Internal Server Error: /
Traceback (most recent call last):
  File "/home/ubuntu/venvs/mysite/lib/python3.8/site-packages/django/core/handlers/exception.py", line 47, in inner
    response = get_response(request)
  File "/home/ubuntu/venvs/mysite/lib/python3.8/site-packages/django/core/handlers/base.py", line 179, in _get_response
    response = wrapped_callback(request, *callback_args, **callback_kwargs)
  File "/home/ubuntu/projects/mysite/neworld/views/base_views.py", line 31, in index
    last_real_day = datetime.datetime.strptime(last_real_date.real_date, "%Y-%m-%d")
AttributeError: 'NoneType' object has no attribute 'real_date'
2021-10-04 00:28:24,138 [INFO] neworld: INFO 레벨로 출력
2021-10-04 00:28:24,141 [ERROR] django.request: Internal Server Error: /
Traceback (most recent call last):
  File "/home/ubuntu/venvs/mysite/lib/python3.8/site-packages/django/core/handlers/exception.py", line 47, in inner
    response = get_response(request)
  File "/home/ubuntu/venvs/mysite/lib/python3.8/site-packages/django/core/handlers/base.py", line 179, in _get_response
    response = wrapped_callback(request, *callback_args, **callback_kwargs)
  File "/home/ubuntu/projects/mysite/neworld/views/base_views.py", line 31, in index
    last_real_day = datetime.datetime.strptime(last_real_date.real_date, "%Y-%m-%d")
AttributeError: 'NoneType' object has no attribute 'real_date'
2021-10-04 00:28:25,999 [INFO] neworld: INFO 레벨로 출력
2021-10-04 00:28:26,002 [ERROR] django.request: Internal Server Error: /
Traceback (most recent call last):
  File "/home/ubuntu/venvs/mysite/lib/python3.8/site-packages/django/core/handlers/exception.py", line 47, in inner
    response = get_response(request)
  File "/home/ubuntu/venvs/mysite/lib/python3.8/site-packages/django/core/handlers/base.py", line 179, in _get_response
    response = wrapped_callback(request, *callback_args, **callback_kwargs)
  File "/home/ubuntu/projects/mysite/neworld/views/base_views.py", line 31, in index
    last_real_day = datetime.datetime.strptime(last_real_date.real_date, "%Y-%m-%d")
AttributeError: 'NoneType' object has no attribute 'real_date'
2021-10-04 00:29:57,900 [INFO] neworld: INFO 레벨로 출력
2021-10-04 00:29:57,903 [ERROR] django.request: Internal Server Error: /
Traceback (most recent call last):
  File "/home/ubuntu/venvs/mysite/lib/python3.8/site-packages/django/core/handlers/exception.py", line 47, in inner
    response = get_response(request)
  File "/home/ubuntu/venvs/mysite/lib/python3.8/site-packages/django/core/handlers/base.py", line 179, in _get_response
    response = wrapped_callback(request, *callback_args, **callback_kwargs)
  File "/home/ubuntu/projects/mysite/neworld/views/base_views.py", line 31, in index
    last_real_day = datetime.datetime.strptime(last_real_date.real_date, "%Y-%m-%d")
AttributeError: 'NoneType' object has no attribute 'real_date'
2021-10-04 00:39:55,102 [INFO] neworld: INFO 레벨로 출력
2021-10-04 00:39:55,105 [ERROR] django.request: Internal Server Error: /
Traceback (most recent call last):
  File "/home/ubuntu/venvs/mysite/lib/python3.8/site-packages/django/core/handlers/exception.py", line 47, in inner
    response = get_response(request)
  File "/home/ubuntu/venvs/mysite/lib/python3.8/site-packages/django/core/handlers/base.py", line 179, in _get_response
    response = wrapped_callback(request, *callback_args, **callback_kwargs)
  File "/home/ubuntu/projects/mysite/neworld/views/base_views.py", line 31, in index
    last_real_day = datetime.datetime.strptime(last_real_date.real_date, "%Y-%m-%d")
AttributeError: 'NoneType' object has no attribute 'real_date'
2021-10-04 00:40:01,272 [INFO] neworld: INFO 레벨로 출력
2021-10-04 00:40:01,274 [ERROR] django.request: Internal Server Error: /
Traceback (most recent call last):
  File "/home/ubuntu/venvs/mysite/lib/python3.8/site-packages/django/core/handlers/exception.py", line 47, in inner
    response = get_response(request)
  File "/home/ubuntu/venvs/mysite/lib/python3.8/site-packages/django/core/handlers/base.py", line 179, in _get_response
    response = wrapped_callback(request, *callback_args, **callback_kwargs)
  File "/home/ubuntu/projects/mysite/neworld/views/base_views.py", line 31, in index
    last_real_day = datetime.datetime.strptime(last_real_date.real_date, "%Y-%m-%d")
AttributeError: 'NoneType' object has no attribute 'real_date'
2021-10-04 00:40:06,005 [INFO] neworld: INFO 레벨로 출력
2021-10-04 00:40:06,008 [ERROR] django.request: Internal Server Error: /
Traceback (most recent call last):
  File "/home/ubuntu/venvs/mysite/lib/python3.8/site-packages/django/core/handlers/exception.py", line 47, in inner
    response = get_response(request)
  File "/home/ubuntu/venvs/mysite/lib/python3.8/site-packages/django/core/handlers/base.py", line 179, in _get_response
    response = wrapped_callback(request, *callback_args, **callback_kwargs)
  File "/home/ubuntu/projects/mysite/neworld/views/base_views.py", line 31, in index
    last_real_day = datetime.datetime.strptime(last_real_date.real_date, "%Y-%m-%d")
AttributeError: 'NoneType' object has no attribute 'real_date'
2021-10-04 00:40:20,032 [INFO] neworld: INFO 레벨로 출력
2021-10-04 00:40:20,035 [ERROR] django.request: Internal Server Error: /
Traceback (most recent call last):
  File "/home/ubuntu/venvs/mysite/lib/python3.8/site-packages/django/core/handlers/exception.py", line 47, in inner
    response = get_response(request)
  File "/home/ubuntu/venvs/mysite/lib/python3.8/site-packages/django/core/handlers/base.py", line 179, in _get_response
    response = wrapped_callback(request, *callback_args, **callback_kwargs)
  File "/home/ubuntu/projects/mysite/neworld/views/base_views.py", line 31, in index
    last_real_day = datetime.datetime.strptime(last_real_date.real_date, "%Y-%m-%d")
AttributeError: 'NoneType' object has no attribute 'real_date'
2021-10-04 00:40:58,412 [INFO] neworld: INFO 레벨로 출력
2021-10-04 00:40:58,415 [ERROR] django.request: Internal Server Error: /
Traceback (most recent call last):
  File "/home/ubuntu/venvs/mysite/lib/python3.8/site-packages/django/core/handlers/exception.py", line 47, in inner
    response = get_response(request)
  File "/home/ubuntu/venvs/mysite/lib/python3.8/site-packages/django/core/handlers/base.py", line 179, in _get_response
    response = wrapped_callback(request, *callback_args, **callback_kwargs)
  File "/home/ubuntu/projects/mysite/neworld/views/base_views.py", line 31, in index
    last_real_day = datetime.datetime.strptime(last_real_date.real_date, "%Y-%m-%d")
AttributeError: 'NoneType' object has no attribute 'real_date'
2021-10-04 00:47:53,644 [ERROR] django.security.DisallowedHost: Invalid HTTP_HOST header: '/tmp/gunicorn.sock:'. The domain name provided is not valid according to RFC 1034/1035.
2021-10-04 00:47:53,652 [WARNING] django.request: Bad Request: /
2021-10-04 00:49:48,069 [INFO] neworld: INFO 레벨로 출력
